Workbook

Sheet Assumptions
A1: Isolated Shunt Amplifier — Tolerance Budget
A2: Rev 2. Blue cells are inputs — change them and every sheet recalculates.
A3: Sources: Skyworks Si8921/22 datasheet; Vishay WSL3637 datasheet; Rev 2 schematic and BOM.
A5: OPERATING CONDITIONS
A6: Max current, ×10 range | B6: 10 | C6: A | D6: Switch position 2. The legend 1 V/10 A is the scale factor, so 10 A gives a 1.0 V full-scale output.
A7: Max current, ×100 range | B7: 5 | C7: A | D7: Switch position 3. The legend 1 V/1 A is the scale factor, so 5 A gives a 5.0 V full-scale output. NOTE: J1 is silkscreened +/-4.5 V, which this exceeds — see the design review.
A8: Temperature excursion from calibration point | B8: 5 | C8: °C | D8: ±°C about the 23 °C trim point. Drives every drift term. 5 = the industry-standard 23 ±5 °C accuracy window. Set to 20 to see the full 0-40 °C operating range.
A9: SHUNT — Vishay WSL3637R0100DEA
A10: Resistance | B10: 0.01 | C10: Ω | D10: 10 mΩ, 4-terminal Kelvin.
A11: Initial tolerance | B11: 0.5 | C11: % | D11: Datasheet: ±0.5 % or ±1.0 % available. ±0.5 % fitted.
A12: TCR | B12: 50 | C12: ppm/°C | D12: Datasheet: ±50 ppm/°C for 0.003 Ω to 0.010 Ω.
A13: Power rating | B13: 3 | C13: W | D13: Datasheet: 3.0 W at 70 °C ambient.
A14: Max operating temperature | B14: 170 | C14: °C | D14: Datasheet: −65 to +170 °C. Derating curve runs to zero here.
A15: Ambient for the power rating | B15: 70 | C15: °C | D15: Datasheet condition for the 3.0 W rating.
A16: Shunt thermal EMF at the terminals | B16: 5 | C16: µV | D16: ESTIMATE — not from a datasheet. Cu-to-alloy junction with a small gradient. Measure to confirm.
A17: ISOLATOR — Si8921BD-IS4R (B grade)
A18: Nominal gain | B18: 8.2 | C18: V/V | D18: Datasheet: 8.2 for Si8921B.
A19: Gain error, max at 25 °C | B19: 0.2 | C19: % | D19: Datasheet: −0.2 / ±0.06 typ / +0.2 %.
A20: Gain drift, worst case | B20: 24 | C20: ppm/°C | D20: Datasheet: −24 / −9 typ / 0 ppm/°C.
A21: Input offset voltage, max at 25 °C | B21: 0.15 | C21: mV | D21: Datasheet Si8921: −0.15 / ±0.04 typ / +0.15 mV. Trimmed out by R28.
A22: Input offset drift, max | B22: 3 | C22: µV/°C | D22: Datasheet: −0.3 / 0.5 typ / 3 µV/°C. NOT trimmable.
A23: Nonlinearity, max | B23: 0.08 | C23: % FS | D23: Datasheet: up to ±0.08 % by grade; 0.003–0.02 % typ.
A24: DIFFERENCE AMP U3 — gain R3/R2
A25: R2, R9 tolerance | B25: 0.05 | C25: % | D25: ERA-6VRW8201V, 8.2 kΩ ±0.05 %.
A26: R2, R9 TCR | B26: 10 | C26: ppm/°C | D26: ERA-6VRW8201V, ±10 ppm/°C.
A27: R3, R20 tolerance | B27: 0.1 | C27: % | D27: RG2012P-103-B-T5, 10 kΩ ±0.1 %.
A28: R3, R20 TCR | B28: 25 | C28: ppm/°C | D28: RG2012P-103-B-T5, ±25 ppm/°C.
A29: SECOND STAGE U8 — high-gain range only
A30: Feedback R7+R10+R11 | B30: 1410 | C30: Ω | D30: 3 × 470 Ω in series, ERA-6AEB471V.
A31: Gain-set R14∥R16∥R18 | B31: 156.67 | C31: Ω | D31: 3 × 470 Ω in parallel.
A32: 470 Ω network tolerance | B32: 0.1 | C32: % | D32: ERA-6AEB471V, ±0.1 %.
A33: 470 Ω network TCR | B33: 25 | C33: ppm/°C | D33: ERA-6AEB471V, ±25 ppm/°C.
A34: Rel1 contact resistance | B34: 0.1 | C34: Ω | D34: Omron G6L-1F, initial max. Rises over contact life.
A35: OFFSET TRIM — R28
A36: R28 pot value | B36: 100 | C36: Ω | D36: As fitted per the schematic. NOTE: the BOM specifies CT94EW103 = 10 kΩ — the BOM line is wrong.
A37: R26, R29 divider | B37: 100000 | C37: Ω | D37: ERA-6AEB104V, 100 kΩ ±0.1 %, ±25 ppm/°C.
A38: Reference divider resistor tolerance | B38: 0.1 | C38: % | D38: ERA-6AEB104V on all four of R26, R29, R22, R17.
A39: +12 V rail | B39: 12 | C39: V | D39: UA78L12 output.
A40: Trimmer settability | B40: 1 | C40: % of span | D40: Rule of thumb for a single-turn cermet. 0.1 % for a 25-turn.
A41: REFERENCE BUFFERS — both LM7321
...

Sheet 10 A range (x10)
A1: 10 A range — total gain ×10, 1.0 V full scale
A2: Every term is ± and expressed as a percentage. Gain terms are % of reading; offset and full-scale terms are % of the 1 V calibrated full scale.
A4: Error term | B4: ± % | C4: Removed by | D4: Derivation
A5: Gain terms — % of reading
A6: R5 shunt initial tolerance | B6: =Assumptions!$B$11 -> 0.5 | C6: Scale factor | D6: Datasheet tolerance. A one-time gain correction removes it entirely.
A7: R5 self-heating at full current | B7: =Assumptions!$B$58*Assumptions!$B$12/10000 -> 0.16666667 | C7: No | D7: Self-heating rise × TCR. Scales with I², so it is negligible at low current and worst at full scale.
A8: R5 ambient drift | B8: =Assumptions!$B$8*Assumptions!$B$12/10000 -> 0.025 | C8: No | D8: Temperature excursion × TCR.
A9: Si8921B gain error at 25 °C | B9: =Assumptions!$B$19 -> 0.2 | C9: Scale factor | D9: Datasheet max. Systematic per part, so calibration removes it.
A10: Si8921B gain drift | B10: =Assumptions!$B$8*Assumptions!$B$20/10000 -> 0.012 | C10: No | D10: Temperature excursion × worst-case gain drift.
A11: U3 resistor ratio R3/R2 | B11: =SQRT(Assumptions!$B$25^2+Assumptions!$B$27^2) -> 0.1118034 | C11: Scale factor | D11: RSS of the two tolerances. These are discrete parts, not a matched network.
A12: U3 TCR mismatch | B12: =(Assumptions!$B$26+Assumptions!$B$28)*Assumptions!$B$8/10000 -> 0.0175 | C12: No | D12: Worst-case differential drift: the two halves have different TCR specs (10 vs 25 ppm/°C) and do not track.
A13: Offset and full-scale terms — % of full scale
A14: Si8921B input offset at 25 °C, max | B14: =Assumptions!$B$21/1000*(Assumptions!$B$18*10/8.2*1)/Assumptions!$B$60*100 -> 0.15 | C14: R28 trim | D14: Datasheet max ±0.15 mV at the shunt input, referred to the output. Shown at full value so the trim's contribution is visible: R28 nulls it completely.
A15: Reference static offset — 2 × LM7321 Vos | B15: =Assumptions!$B$47*SQRT(2)/1000*1/Assumptions!$B$60*100 -> 0.70710678 | C15: R28 trim | D15: Two LM7321 buffers at ±5 mV max, RSS. Appears directly as a DiffAmpRef-to-ISenseRTN difference. R28 nulls it — but see the Trim range tab: at datasheet limits this alone exceeds the 100 Ω pot's ±3 mV range.
A16: Reference static offset — divider tolerance | B16: =Assumptions!$B$39*Assumptions!$B$38/100/4*SQRT(4)*1/Assumptions!$B$60*100 -> 0.6 | C16: R28 trim | D16: Four 0.1 % resistors forming two dividers; RSS of the four sensitivities, ±6 mV. Also nulled by R28.
A17: Reference static offset — Ib × 10 kΩ asymmetry | B17: =Assumptions!$B$44*0.000000001*(Assumptions!$B$42-Assumptions!$B$43)*1/Assumptions!$B$60*100 -> 0.05 | C17: R28 trim | D17: Common-mode Ib acting on the R21 asymmetry. Static part nulls out; the drift part does not — see the separate reference-drift line.
A18: LM7321 Vos drift, two devices | B18: =Assumptions!$B$49*Assumptions!$B$8*SQRT(2)/1000000*1/Assumptions!$B$60*100 -> 0.001767767 | C18: No | D18: ±2.5 µV/°C per device over the temperature excursion, RSS of two. Not trimmable.
A19: Si8921B input offset drift | B19: =Assumptions!$B$22*Assumptions!$B$8/1000*(Assumptions!$B$18*10/8.2*1)/Assumptions!$B$60/10 -> 0.015 | C19: No | D19: Offset drift × temperature excursion, referred to the output and divided by full scale. THE dominant term on the high-gain range: the shunt only develops 10 mV at 1 A, so input offset weighs ten times more heavily.
A20: Shunt thermal EMF | B20: =Assumptions!$B$16/1000*(Assumptions!$B$18*10/8.2*1)/Assumptions!$B$60/10 -> 0.005 | C20: Partly | D20: ESTIMATE. A static EMF trims out; the part that varies with the thermal gradient does not.
A21: Si8921B nonlinearity | B21: =Assumptions!$B$23 -> 0.08 | C21: No | D21: Datasheet max. Not removable by a two-point calibration.
A22: R28 trim resolution | B22: =Assumptions!$B$54*1/(Assumptions!$B$60*1000)*100 -> 0.0059970015 | C22: No | D22: Smallest settable step at DiffAmpRef, multiplied by the U8 gain, as a fraction of full scale. This is how finely zero can be set — not an error in the parts.
A23: Reference drift, DiffAmpRef vs ISenseRTN | B23: =Assumptions!$B$46*Assumptions!$B$8/100*Assumptions!$B$44*0.000000001*((Assumptions!$B$42-Assumptions!$B$43)+Assumptions!$B$45/100*(Assumptions!$B$42+Assumptions!$B$43)/2)*1/Assumptions!$B$60*100 -> 0.00525 | C23: No | D23: Both references use an LM7321, so bias current is MATCHED and its common-mode part cancels — but only to the extent the two source impedances match, and they differ by R21 = 10 kΩ. The first bracket is that 10 kΩ asymmetry acting on common-mode Ib drift; the second is device mismatch acting on the average impedance. ESTIMATE — bench-measure DiffAmpRef minus ISenseRTN against temperature after trimming.
A25: TOTALS — error at a full-scale reading
A26: As built, worst case (linear sum) | B26: =SUM(B6,B7,B8,B9,B10,B11,B12)+SUM(B14,B15,B16,B17,B18,B19,B20,B21,B22,B23) -> 2.6530916 | D26: Every term at its datasheet limit, all pushing the same way, nothing trimmed or calibrated.
A27: As built, RSS | B27: =SQRT(SUMSQ(B6,B7,B8,B9,B10,B11,B12)+SUMSQ(B14,B15,B16,B17,B18,B19,B20,B21,B22,B23)) -> 1.1059248 | D27: Same, combined statistically.
A28: AS SHIPPED — R28 trimmed, worst case | B28: =SUMIF($C$6:$C$23,"No",$B$6:$B$23)+SUMIF($C$6:$C$23,"Partly",$B$6:$B$23)+SUMIF($C$6:$C$23,"Scale factor",$B$6:$B$23) -> 1.1459848 | D28: THE NUMBER TO PUBLISH. R28 is trimmed on every board, so every static offset is gone before the unit ships. Nothing on the board trims gain, so all the gain terms remain.
A29: AS SHIPPED — R28 trimmed, RSS | B29: =SQRT(SUMPRODUCT((($C$6:$C$23<>"R28 trim"))*$B$6:$B$23^2)) -> 0.5814376 | D29: The realistic out-of-the-box figure. This is what a user gets with no action on their part.
A30: + user scale factor, worst case | B30: =SUMIF($C$6:$C$23,"No",$B$6:$B$23)+SUMIF($C$6:$C$23,"Partly",$B$6:$B$23) -> 0.33418144 | D30: NOT A BOARD FEATURE — there is no gain trimmer. This row is only reachable if the user measures a known current and applies a scale factor in their own DAQ or software. Shown so the ceiling is visible.
A31: + user scale factor, RSS | B31: =SQRT(SUMPRODUCT((($C$6:$C$23="No")+($C$6:$C$23="Partly"))*$B$6:$B$23^2)) -> 0.18859926 | D31: Best achievable, and only with user-side correction. Do not publish this as the instrument spec.

Sheet 5 A range (x100)
A1: 5 A range — total gain ×100, 5.0 V full scale
A2: Every term is ± and expressed as a percentage. Gain terms are % of reading; offset and full-scale terms are % of the 1 V calibrated full scale.
A4: Error term | B4: ± % | C4: Removed by | D4: Derivation
A5: Gain terms — % of reading
A6: R5 shunt initial tolerance | B6: =Assumptions!$B$11 -> 0.5 | C6: Scale factor | D6: Datasheet tolerance. A one-time gain correction removes it entirely.
A7: R5 self-heating at full current | B7: =Assumptions!$B$64*Assumptions!$B$12/10000 -> 0.041666667 | C7: No | D7: Self-heating rise × TCR. Scales with I², so it is negligible at low current and worst at full scale.
A8: R5 ambient drift | B8: =Assumptions!$B$8*Assumptions!$B$12/10000 -> 0.025 | C8: No | D8: Temperature excursion × TCR.
A9: Si8921B gain error at 25 °C | B9: =Assumptions!$B$19 -> 0.2 | C9: Scale factor | D9: Datasheet max. Systematic per part, so calibration removes it.
A10: Si8921B gain drift | B10: =Assumptions!$B$8*Assumptions!$B$20/10000 -> 0.012 | C10: No | D10: Temperature excursion × worst-case gain drift.
A11: U3 resistor ratio R3/R2 | B11: =SQRT(Assumptions!$B$25^2+Assumptions!$B$27^2) -> 0.1118034 | C11: Scale factor | D11: RSS of the two tolerances. These are discrete parts, not a matched network.
A12: U3 TCR mismatch | B12: =(Assumptions!$B$26+Assumptions!$B$28)*Assumptions!$B$8/10000 -> 0.0175 | C12: No | D12: Worst-case differential drift: the two halves have different TCR specs (10 vs 25 ppm/°C) and do not track.
A13: U8 network ratio (6 × 470 Ω) | B13: =(Assumptions!$B$30/Assumptions!$B$31)/(1+Assumptions!$B$30/Assumptions!$B$31)*SQRT((Assumptions!$B$32/SQRT(3))^2*2) -> 0.073484536 | C13: Scale factor | D13: Gain sensitivity × RSS of the series and parallel groups; three parts per group average down by √3.
A14: U8 TCR mismatch | B14: =(Assumptions!$B$30/Assumptions!$B$31)/(1+Assumptions!$B$30/Assumptions!$B$31)*Assumptions!$B$33*Assumptions!$B$8/10000 -> 0.011249976 | C14: No | D14: Same part type throughout, so this is pessimistic — real tracking will be better.
A15: Rel1 contact resistance | B15: =(Assumptions!$B$30/Assumptions!$B$31)/(1+Assumptions!$B$30/Assumptions!$B$31)*Assumptions!$B$34/Assumptions!$B$31*100 -> 0.057445464 | C15: Scale factor | D15: Contact resistance in series with the gain-set leg. Systematic, but it grows with contact wear, so calibration ages out.
A16: Offset and full-scale terms — % of full scale
A17: Si8921B input offset at 25 °C, max | B17: =Assumptions!$B$21/1000*(Assumptions!$B$18*10/8.2*10)/Assumptions!$B$66*100 -> 0.3 | C17: R28 trim | D17: Datasheet max ±0.15 mV at the shunt input, referred to the output. Shown at full value so the trim's contribution is visible: R28 nulls it completely.
A18: Reference static offset — 2 × LM7321 Vos | B18: =Assumptions!$B$47*SQRT(2)/1000*10/Assumptions!$B$66*100 -> 1.4142136 | C18: R28 trim | D18: Two LM7321 buffers at ±5 mV max, RSS. Appears directly as a DiffAmpRef-to-ISenseRTN difference. R28 nulls it — but see the Trim range tab: at datasheet limits this alone exceeds the 100 Ω pot's ±3 mV range.
A19: Reference static offset — divider tolerance | B19: =Assumptions!$B$39*Assumptions!$B$38/100/4*SQRT(4)*10/Assumptions!$B$66*100 -> 1.2 | C19: R28 trim | D19: Four 0.1 % resistors forming two dividers; RSS of the four sensitivities, ±6 mV. Also nulled by R28.
A20: Reference static offset — Ib × 10 kΩ asymmetry | B20: =Assumptions!$B$44*0.000000001*(Assumptions!$B$42-Assumptions!$B$43)*10/Assumptions!$B$66*100 -> 0.1 | C20: R28 trim | D20: Common-mode Ib acting on the R21 asymmetry. Static part nulls out; the drift part does not — see the separate reference-drift line.
A21: LM7321 Vos drift, two devices | B21: =Assumptions!$B$49*Assumptions!$B$8*SQRT(2)/1000000*10/Assumptions!$B$66*100 -> 0.0035355339 | C21: No | D21: ±2.5 µV/°C per device over the temperature excursion, RSS of two. Not trimmable.
A22: Si8921B input offset drift | B22: =Assumptions!$B$22*Assumptions!$B$8/1000*(Assumptions!$B$18*10/8.2*10)/Assumptions!$B$66/10 -> 0.03 | C22: No | D22: Offset drift × temperature excursion, referred to the output and divided by full scale. THE dominant term on the high-gain range: the shunt only develops 10 mV at 1 A, so input offset weighs ten times more heavily.
A23: Shunt thermal EMF | B23: =Assumptions!$B$16/1000*(Assumptions!$B$18*10/8.2*10)/Assumptions!$B$66/10 -> 0.01 | C23: Partly | D23: ESTIMATE. A static EMF trims out; the part that varies with the thermal gradient does not.
A24: Si8921B nonlinearity | B24: =Assumptions!$B$23 -> 0.08 | C24: No | D24: Datasheet max. Not removable by a two-point calibration.
A25: R28 trim resolution | B25: =Assumptions!$B$54*10/(Assumptions!$B$66*1000)*100 -> 0.011994003 | C25: No | D25: Smallest settable step at DiffAmpRef, multiplied by the U8 gain, as a fraction of full scale. This is how finely zero can be set — not an error in the parts.
A26: Reference drift, DiffAmpRef vs ISenseRTN | B26: =Assumptions!$B$46*Assumptions!$B$8/100*Assumptions!$B$44*0.000000001*((Assumptions!$B$42-Assumptions!$B$43)+Assumptions!$B$45/100*(Assumptions!$B$42+Assumptions!$B$43)/2)*10/Assumptions!$B$66*100 -> 0.0105 | C26: No | D26: Both references use an LM7321, so bias current is MATCHED and its common-mode part cancels — but only to the extent the two source impedances match, and they differ by R21 = 10 kΩ. The first bracket is that 10 kΩ asymmetry acting on common-mode Ib drift; the second is device mismatch acting on the average impedance. ESTIMATE — bench-measure DiffAmpRef minus ISenseRTN against temperature after trimming.
A28: TOTALS — error at a full-scale reading
A29: As built, worst case (linear sum) | B29: =SUM(B6,B7,B8,B9,B10,B11,B12,B13,B14,B15)+SUM(B17,B18,B19,B20,B21,B22,B23,B24,B25,B26) -> 4.2103931 | D29: Every term at its datasheet limit, all pushing the same way, nothing trimmed or calibrated.
A30: As built, RSS | B30: =SQRT(SUMSQ(B6,B7,B8,B9,B10,B11,B12,B13,B14,B15)+SUMSQ(B17,B18,B19,B20,B21,B22,B23,B24,B25,B26)) -> 1.9651474 | D30: Same, combined statistically.
A31: AS SHIPPED — R28 trimmed, worst case | B31: =SUMIF($C$6:$C$26,"No",$B$6:$B$26)+SUMIF($C$6:$C$26,"Partly",$B$6:$B$26)+SUMIF($C$6:$C$26,"Scale factor",$B$6:$B$26) -> 1.1961796 | D31: THE NUMBER TO PUBLISH. R28 is trimmed on every board, so every static offset is gone before the unit ships. Nothing on the board trims gain, so all the gain terms remain.
A32: AS SHIPPED — R28 trimmed, RSS | B32: =SQRT(SUMPRODUCT((($C$6:$C$26<>"R28 trim"))*$B$6:$B$26^2)) -> 0.56727814 | D32: The realistic out-of-the-box figure. This is what a user gets with no action on their part.
A33: + user scale factor, worst case | B33: =SUMIF($C$6:$C$26,"No",$B$6:$B$26)+SUMIF($C$6:$C$26,"Partly",$B$6:$B$26) -> 0.25344618 | D33: NOT A BOARD FEATURE — there is no gain trimmer. This row is only reachable if the user measures a known current and applies a scale factor in their own DAQ or software. Shown so the ceiling is visible.
A34: + user scale factor, RSS | B34: =SQRT(SUMPRODUCT((($C$6:$C$26="No")+($C$6:$C$26="Partly"))*$B$6:$B$26^2)) -> 0.10297829 | D34: Best achievable, and only with user-side correction. Do not publish this as the instrument spec.

Sheet R28 sizing
A1: R28 offset trimmer — range versus resolution
A2: Trim range must cover the untrimmed offset; the settable step sets how finely zero can be placed. Output figures are on the ×100 (5 A) range, where a DiffAmpRef error is multiplied by 10 against a 5 V full scale.
A4: R28 (Ω) | B4: Span (mV) | C4: Range (±mV) | D4: Step, 1-turn (µV) | E4: → % FS at ×100 | F4: Step, 25-turn (µV) | G4: → % FS at ×100
A5: 10 | B5: =Assumptions!$B$39*A5/(2*Assumptions!$B$37+A5)*1000 -> 0.59997 | C5: =B5/2 -> 0.299985 | D5: =B5*1000*0.01 -> 5.9997 | E5: =B5*0.01*10/(Assumptions!$B$66*1000)*100 -> 0.00119994 | F5: =B5*1000*0.001 -> 0.59997 | G5: =B5*0.001*10/(Assumptions!$B$66*1000)*100 -> 0.000119994
A6: 20 | B6: =Assumptions!$B$39*A6/(2*Assumptions!$B$37+A6)*1000 -> 1.19988 | C6: =B6/2 -> 0.59994001 | D6: =B6*1000*0.01 -> 11.9988 | E6: =B6*0.01*10/(Assumptions!$B$66*1000)*100 -> 0.00239976 | F6: =B6*1000*0.001 -> 1.19988 | G6: =B6*0.001*10/(Assumptions!$B$66*1000)*100 -> 0.000239976
A7: 50 | B7: =Assumptions!$B$39*A7/(2*Assumptions!$B$37+A7)*1000 -> 2.9992502 | C7: =B7/2 -> 1.4996251 | D7: =B7*1000*0.01 -> 29.992502 | E7: =B7*0.01*10/(Assumptions!$B$66*1000)*100 -> 0.0059985004 | F7: =B7*1000*0.001 -> 2.9992502 | G7: =B7*0.001*10/(Assumptions!$B$66*1000)*100 -> 0.00059985004
A8: 100 | B8: =Assumptions!$B$39*A8/(2*Assumptions!$B$37+A8)*1000 -> 5.9970015 | C8: =B8/2 -> 2.9985007 | D8: =B8*1000*0.01 -> 59.970015 | E8: =B8*0.01*10/(Assumptions!$B$66*1000)*100 -> 0.011994003 | F8: =B8*1000*0.001 -> 5.9970015 | G8: =B8*0.001*10/(Assumptions!$B$66*1000)*100 -> 0.0011994003
A9: 200 | B9: =Assumptions!$B$39*A9/(2*Assumptions!$B$37+A9)*1000 -> 11.988012 | C9: =B9/2 -> 5.994006 | D9: =B9*1000*0.01 -> 119.88012 | E9: =B9*0.01*10/(Assumptions!$B$66*1000)*100 -> 0.023976024 | F9: =B9*1000*0.001 -> 11.988012 | G9: =B9*0.001*10/(Assumptions!$B$66*1000)*100 -> 0.0023976024
A10: 500 | B10: =Assumptions!$B$39*A10/(2*Assumptions!$B$37+A10)*1000 -> 29.925187 | C10: =B10/2 -> 14.962594 | D10: =B10*1000*0.01 -> 299.25187 | E10: =B10*0.01*10/(Assumptions!$B$66*1000)*100 -> 0.059850374 | F10: =B10*1000*0.001 -> 29.925187 | G10: =B10*0.001*10/(Assumptions!$B$66*1000)*100 -> 0.0059850374
A11: 1000 | B11: =Assumptions!$B$39*A11/(2*Assumptions!$B$37+A11)*1000 -> 59.701493 | C11: =B11/2 -> 29.850746 | D11: =B11*1000*0.01 -> 597.01493 | E11: =B11*0.01*10/(Assumptions!$B$66*1000)*100 -> 0.11940299 | F11: =B11*1000*0.001 -> 59.701493 | G11: =B11*0.001*10/(Assumptions!$B$66*1000)*100 -> 0.011940299
A12: 2000 | B12: =Assumptions!$B$39*A12/(2*Assumptions!$B$37+A12)*1000 -> 118.81188 | C12: =B12/2 -> 59.405941 | D12: =B12*1000*0.01 -> 1188.1188 | E12: =B12*0.01*10/(Assumptions!$B$66*1000)*100 -> 0.23762376 | F12: =B12*1000*0.001 -> 118.81188 | G12: =B12*0.001*10/(Assumptions!$B$66*1000)*100 -> 0.023762376
A13: 5000 | B13: =Assumptions!$B$39*A13/(2*Assumptions!$B$37+A13)*1000 -> 292.68293 | C13: =B13/2 -> 146.34146 | D13: =B13*1000*0.01 -> 2926.8293 | E13: =B13*0.01*10/(Assumptions!$B$66*1000)*100 -> 0.58536585 | F13: =B13*1000*0.001 -> 292.68293 | G13: =B13*0.001*10/(Assumptions!$B$66*1000)*100 -> 0.058536585
A14: 10000 | B14: =Assumptions!$B$39*A14/(2*Assumptions!$B$37+A14)*1000 -> 571.42857 | C14: =B14/2 -> 285.71429 | D14: =B14*1000*0.01 -> 5714.2857 | E14: =B14*0.01*10/(Assumptions!$B$66*1000)*100 -> 1.1428571 | F14: =B14*1000*0.001 -> 571.42857 | G14: =B14*0.001*10/(Assumptions!$B$66*1000)*100 -> 0.11428571
A16: 100 Ω is the value fitted per the schematic and confirmed on hardware: ±3 mV of range with a 60 µV step, which places zero to 0.06 % of full scale on the ×100 range.
A17: The BOM line for R28 (CT94EW103) is a 10 kΩ part. At 10 kΩ the step is 5.7 mV, or 5.7 % of full scale at ×100 — the trim would be unusably coarse. The BOM is wrong, not the schematic.

Sheet Trim range
A1: R28 trim range — what the pot has to absorb
A2: Every static offset in the chain is nulled by R28, so none of it reaches the output. The question this sheet answers is whether the pot has the RANGE to do it.
A4: Static offset term | B4: Worst case (mV) | C4: Typical (mV) | D4: Notes
A5: Reference divider mismatch, both dividers | B5: =Assumptions!$B$39*Assumptions!$B$38/100*1000 -> 12 | C5: =Assumptions!$B$39*Assumptions!$B$38/100/4*SQRT(4)*1000/3 -> 2 | D5: Four 0.1 % resistors. Worst case is both dividers at opposite limits. The typical column takes the RSS and divides by 3, on the usual assumption that a thin-film tolerance is roughly a 3-sigma bound — these parts normally land far inside spec.
A6: LM7321 Vos, two devices | B6: =2*Assumptions!$B$47 -> 10 | C6: =Assumptions!$B$48*SQRT(2) -> 0.49497475 | D6: Datasheet ±5 mV max, ±0.35 mV typ. This is the term that decides whether a board trims.
A7: Ib through the R21 asymmetry | B7: =Assumptions!$B$44*0.000000001*(Assumptions!$B$42-Assumptions!$B$43)*1000 -> 0.5 | C7: =Assumptions!$B$44*0.000000001*(Assumptions!$B$42-Assumptions!$B$43)*1000 -> 0.5 | D7: Datasheet Ib typ is 0.4 µA, which alone would need 4 mV. The assumed 50 nA reflects the hardware evidence, not the datasheet.
A8: Si8921B input offset, referred to DiffAmpRef | B8: =Assumptions!$B$21*Assumptions!$B$18*10/8.2 -> 1.5 | C8: =0.04*Assumptions!$B$18*10/8.2 -> 0.4 | D8: ±0.15 mV max at the shunt, amplified by the isolator and U3 before it reaches the reference node.
A9: TOTAL to be absorbed (linear sum) | B9: =SUM(B5:B8) -> 24 | C9: =SUM(C5:C8) -> 3.3949747
A11: R28 range available (± mV) | B11: =Assumptions!$B$53/2 -> 2.9985007 | D11: Half the span across the pot element, from the Assumptions sheet.
A12: Margin, worst case | B12: =B11-B9 -> -21.001499 | D12: Negative means a board built from worst-case parts could not be trimmed to zero.
A13: Margin, typical | B13: =B11-C9 -> -0.396474 | D13: Positive, comfortably — which is why the fitted 100 Ω works on hardware.
A15: Reading this sheet: the fitted 100 Ω pot trims correctly on hardware, which is itself a measurement — it
A16: says the parts actually fitted sit near their typical values rather than their datasheet limits.
A18: But the worst-case margin is negative, and that is a production-yield question rather than a defect. A board
A19: built from two badly-offset LM7321s could not be zeroed. If more than a handful are ever built, 200 Ω doubles
A20: the range to ±6 mV while still resolving to 0.12 % of full scale on the ×100 range — see the R28 sizing tab.
A22: Changing R21 to 100 Ω (see the design review) also removes the Ib term from this budget entirely.
A24: Note that even the typical column here is conservative. The hardware bounds the real total below the
A25: ±3 mV the pot provides, so the fitted parts are doing better than these figures suggest.

Sheet Specification
A1: Accuracy specification, in instrument form
A2: Gain terms scale with the reading; offset terms are fixed in amps. The usual ±(% of reading + fixed) form separates them, and is far more useful than a single percentage — at 10 % of range the fixed term dominates.
B4: 10 A range (×10) | D4: 5 A range (×100)
A5: Specification | B5: % of reading | C5: + fixed | D5: % of reading | E5: + fixed
A6: As shipped — linear worst case (a bound, not a prediction) | B6: =SUM('10 A range (x10)'!$B$6:$B$12) -> 1.0329701 | C6: =((SUMIF('10 A range (x10)'!$C$14:$C$23,"No",'10 A range (x10)'!$B$14:$B$23))+(SUMIF('10 A range (x10)'!$C$14:$C$23,"Partly",'10 A range (x10)'!$B$14:$B$23)))/100*Assumptions!$B$6*1000 -> 11.301477 | D6: =SUM('5 A range (x100)'!$B$6:$B$15) -> 1.05015 | E6: =((SUMIF('5 A range (x100)'!$C$17:$C$26,"No",'5 A range (x100)'!$B$17:$B$26))+(SUMIF('5 A range (x100)'!$C$17:$C$26,"Partly",'5 A range (x100)'!$B$17:$B$26)))/100*Assumptions!$B$7*1000 -> 7.3014768
A7: As shipped — typical (pure RSS) | B7: =SQRT(SUMSQ('10 A range (x10)'!$B$6:$B$12)) -> 0.57563272 | C7: =(SQRT((SQRT(SUMPRODUCT(('10 A range (x10)'!$C$14:$C$23="No")*'10 A range (x10)'!$B$14:$B$23^2)))^2+(SQRT(SUMPRODUCT(('10 A range (x10)'!$C$14:$C$23="Partly")*'10 A range (x10)'!$B$14:$B$23^2)))^2))/100*Assumptions!$B$6*1000 -> 8.195518 | D7: =SQRT(SUMSQ('5 A range (x100)'!$B$6:$B$15)) -> 0.56048005 | E7: =(SQRT((SQRT(SUMPRODUCT(('5 A range (x100)'!$C$17:$C$26="No")*'5 A range (x100)'!$B$17:$B$26^2)))^2+(SQRT(SUMPRODUCT(('5 A range (x100)'!$C$17:$C$26="Partly")*'5 A range (x100)'!$B$17:$B$26^2)))^2))/100*Assumptions!$B$7*1000 -> 4.3779579
A8: + user gain calibration, worst case | B8: =SUMIF('10 A range (x10)'!$C$6:$C$12,"No",'10 A range (x10)'!$B$6:$B$12) -> 0.22116667 | C8: =((SUMIF('10 A range (x10)'!$C$14:$C$23,"No",'10 A range (x10)'!$B$14:$B$23))+(SUMIF('10 A range (x10)'!$C$14:$C$23,"Partly",'10 A range (x10)'!$B$14:$B$23)))/100*Assumptions!$B$6*1000 -> 11.301477 | D8: =SUMIF('5 A range (x100)'!$C$6:$C$15,"No",'5 A range (x100)'!$B$6:$B$15) -> 0.10741664 | E8: =((SUMIF('5 A range (x100)'!$C$17:$C$26,"No",'5 A range (x100)'!$B$17:$B$26))+(SUMIF('5 A range (x100)'!$C$17:$C$26,"Partly",'5 A range (x100)'!$B$17:$B$26)))/100*Assumptions!$B$7*1000 -> 7.3014768
A9: + user gain calibration, typical | B9: =SQRT(SUMPRODUCT(('10 A range (x10)'!$C$6:$C$12="No")*'10 A range (x10)'!$B$6:$B$12^2)) -> 0.16986179 | C9: =(SQRT((SQRT(SUMPRODUCT(('10 A range (x10)'!$C$14:$C$23="No")*'10 A range (x10)'!$B$14:$B$23^2)))^2+(SQRT(SUMPRODUCT(('10 A range (x10)'!$C$14:$C$23="Partly")*'10 A range (x10)'!$B$14:$B$23^2)))^2))/100*Assumptions!$B$6*1000 -> 8.195518 | D9: =SQRT(SUMPRODUCT(('5 A range (x100)'!$C$6:$C$15="No")*'5 A range (x100)'!$B$6:$B$15^2)) -> 0.054202611 | E9: =(SQRT((SQRT(SUMPRODUCT(('5 A range (x100)'!$C$17:$C$26="No")*'5 A range (x100)'!$B$17:$B$26^2)))^2+(SQRT(SUMPRODUCT(('5 A range (x100)'!$C$17:$C$26="Partly")*'5 A range (x100)'!$B$17:$B$26^2)))^2))/100*Assumptions!$B$7*1000 -> 4.3779579
A11: Worked examples — total error
A12: As shipped, typical, at full scale | B12: =1*Assumptions!$B$6*1000 -> 10000 | C12: =B7/100*1*Assumptions!$B$6*1000+C7 -> 65.75879 | D12: =1*Assumptions!$B$7*1000 -> 5000 | E12: =D7/100*1*Assumptions!$B$7*1000+E7 -> 32.40196
A13: As shipped, typical, at 50 % of range | B13: =0.5*Assumptions!$B$6*1000 -> 5000 | C13: =B7/100*0.5*Assumptions!$B$6*1000+C7 -> 36.977154 | D13: =0.5*Assumptions!$B$7*1000 -> 2500 | E13: =D7/100*0.5*Assumptions!$B$7*1000+E7 -> 18.389959
A14: As shipped, typical, at 10 % of range | B14: =0.1*Assumptions!$B$6*1000 -> 1000 | C14: =B7/100*0.1*Assumptions!$B$6*1000+C7 -> 13.951845 | D14: =0.1*Assumptions!$B$7*1000 -> 500 | E14: =D7/100*0.1*Assumptions!$B$7*1000+E7 -> 7.1803581
A16: The fixed term is NOT un-nulled offset. Every static offset term is classified 'R28 trim' on the range
A17: sheets and is already excluded here — static offset is zero. What remains is what zeroing cannot reach:
A18: drift that appears after the trim, Si8921 nonlinearity (which is not an offset at all), and the finite
A19: resolution of the pot. It does not shrink as the reading does, so the error as a percentage of reading
A20: grows below full scale — at 10 % of range it roughly doubles.
A22: The fixed term is therefore a strong function of the temperature excursion on the Assumptions sheet.
A23: At the ±20 °C assumed here it is 17.9 mA and 13.9 mA; re-zeroing at the working temperature takes it to
A24: 8.6 mA and 4.6 mA, at which point it is almost entirely nonlinearity and cannot be improved by trimming.
A26: The 'as shipped' rows are the instrument's specification. The calibrated rows need the user to measure a
A27: known current and apply a scale factor in their own system — there is no gain trim on the board.
A29: RECOMMENDED PUBLISHED SPEC
A30: Hybrid: batch bias + RSS | B30: =('10 A range (x10)'!$B$6+'10 A range (x10)'!$B$9)+SQRT(SUMSQ('10 A range (x10)'!$B$6:$B$12)-'10 A range (x10)'!$B$6^2-'10 A range (x10)'!$B$9^2+SUMPRODUCT((('10 A range (x10)'!$C$14:$C$23<>"R28 trim"))*'10 A range (x10)'!$B$14:$B$23^2)) -> 0.91924799 | C30: =((SUMIF('10 A range (x10)'!$C$14:$C$23,"No",'10 A range (x10)'!$B$14:$B$23))+(SUMIF('10 A range (x10)'!$C$14:$C$23,"Partly",'10 A range (x10)'!$B$14:$B$23)))/100*Assumptions!$B$6*1000 -> 11.301477 | D30: =('5 A range (x100)'!$B$6+'5 A range (x100)'!$B$9)+SQRT(SUMSQ('5 A range (x100)'!$B$6:$B$15)-'5 A range (x100)'!$B$6^2-'5 A range (x100)'!$B$9^2+SUMPRODUCT((('5 A range (x100)'!$C$17:$C$26<>"R28 trim"))*'5 A range (x100)'!$B$17:$B$26^2)) -> 0.87833813 | E30: =((SUMIF('5 A range (x100)'!$C$17:$C$26,"No",'5 A range (x100)'!$B$17:$B$26))+(SUMIF('5 A range (x100)'!$C$17:$C$26,"Partly",'5 A range (x100)'!$B$17:$B$26)))/100*Assumptions!$B$7*1000 -> 7.3014768 | F30: <- round UP to publish
A32: METHOD. A linear worst-case sum assumes every tolerance lands at its limit and all in the same direction.
A33: A Monte Carlo over 2 million boards, with every tolerance UNIFORM within its limit (the most conservative
A34: distribution assumption), never once reached it: the median was 22 % of the worst case, the 99.9th
A35: percentile 73 %, and the probability of exceeding 1.0 % was about 1 in 125,000. Under a normal
A36: distribution with the limit at 3 sigma it never exceeded 0.87 %. So the linear sum is a bound, not a
A37: figure any real board will produce.
A39: But pure RSS is too optimistic, because independence fails in one place: a reel. Boards built from one
A40: reel of shunts and one tube of isolators share the same offset from nominal, so those terms act as a
A41: common batch bias rather than averaging out.
A43: The hybrid row above is the standard resolution: hold the two dominant, batch-correlated initial-tolerance
A44: terms (R5 at +/-0.5 % and the Si8921 gain error at +/-0.2 %) at their limits, and RSS everything else.
A45: That gives 0.92 % and 0.88 %, which is what should be published.
